Workbook

Sheet Recert Status
A1: Kentucky EMT recertification status
A2: Change the yellow expiration date and the hours recalculate for that cycle only: January 1 of the year before expiration through December 31 of the expiration year. Example: 12/31/2026 uses 2025 and 2026. 12/31/2027 uses 2026 and 2027.
A4: Met | B4: =COUNTIF(N8:N210,"Met") -> 0 | C4: Short | D4: =COUNTIF(N8:N210,"Short") -> 155 | E4: Needs exp date | F4: =COUNTIF(N8:N210,"Set exp date") -> 23
A7: Attendee | B7: KEMSIS ID | C7: Current Exp Date | D7: Cycle Start | E7: Cycle End | F7: =Requirements!A5&" ("&TEXT(Requirements!B5,"0")&")" -> Airway (4) | G7: =Requirements!A6&" ("&TEXT(Requirements!B6,"0")&")" -> Cardiovascular (5) | H7: =Requirements!A7&" ("&TEXT(Requirements!B7,"0")&")" -> Trauma (3) | I7: =Requirements!A8&" ("&TEXT(Requirements!B8,"0")&")" -> Medical (6) | J7: =Requirements!A9&" ("&TEXT(Requirements!B9,"0")&")" -> Operations (2) | K7: =Requirements!A10&" ("&TEXT(Requirements!B10,"0")&")" -> PAHT (1) | L7: =Requirements!A11&" ("&TEXT(Requirements!B11,"0")&")" -> SVAT (1) | M7: =Requirements!A12&" ("&TEXT(Requirements!B12,"0")&")" -> CPR/AED (1) | N7: Status | O7: Still needed
A8: Abell, Jeremy | B8: 1118034 | C8: 46387 | D8: =IF(C8="","",DATE(YEAR(C8)-1,1,1)) -> 45658 | E8: =IF(C8="","",DATE(YEAR(C8),12,31)) -> 46387 | F8: =IF(OR(A8="",C8=""),"",SUMPRODUCT(('Training Detail'!$A$5:$A$5000=A8)*('Training Detail'!$M$5:$M$5000=Standards!A2)*('Training Detail'!$G$5:$G$5000>=D8)*('Training Detail'!$G$5:$G$5000<=E8)*('Training Detail'!$P$5:$P$5000))) -> 2 | G8: =IF(OR(A8="",C8=""),"",SUMPRODUCT(('Training Detail'!$A$5:$A$5000=A8)*('Training Detail'!$M$5:$M$5000=Standards!A3)*('Training Detail'!$G$5:$G$5000>=D8)*('Training Detail'!$G$5:$G$5000<=E8)*('Training Detail'!$P$5:$P$5000))) -> 0 | H8: =IF(OR(A8="",C8=""),"",SUMPRODUCT(('Training Detail'!$A$5:$A$5000=A8)*('Training Detail'!$M$5:$M$5000=Standards!A4)*('Training Detail'!$G$5:$G$5000>=D8)*('Training Detail'!$G$5:$G$5000<=E8)*('Training Detail'!$P$5:$P$5000))) -> 2.5 | I8: =IF(OR(A8="",C8=""),"",SUMPRODUCT(('Training Detail'!$A$5:$A$5000=A8)*('Training Detail'!$M$5:$M$5000=Standards!A5)*('Training Detail'!$G$5:$G$5000>=D8)*('Training Detail'!$G$5:$G$5000<=E8)*('Training Detail'!$P$5:$P$5000))) -> 5 | J8: =IF(OR(A8="",C8=""),"",SUMPRODUCT(('Training Detail'!$A$5:$A$5000=A8)*('Training Detail'!$M$5:$M$5000=Standards!A6)*('Training Detail'!$G$5:$G$5000>=D8)*('Training Detail'!$G$5:$G$5000<=E8)*('Training Detail'!$P$5:$P$5000))) -> 1 | K8: =IF(OR(A8="",C8=""),"",SUMPRODUCT(('Training Detail'!$A$5:$A$5000=A8)*('Training Detail'!$M$5:$M$5000=Standards!A7)*('Training Detail'!$G$5:$G$5000>=D8)*('Training Detail'!$G$5:$G$5000<=E8)*('Training Detail'!$P$5:$P$5000))) -> 1 | L8: =IF(OR(A8="",C8=""),"",SUMPRODUCT(('Training Detail'!$A$5:$A$5000=A8)*('Training Detail'!$M$5:$M$5000=Standards!A8)*('Training Detail'!$G$5:$G$5000>=D8)*('Training Detail'!$G$5:$G$5000<=E8)*('Training Detail'!$P$5:$P$5000))) -> 1 | M8: =IF(OR(A8="",C8=""),"",SUMPRODUCT(('Training Detail'!$A$5:$A$5000=A8)*('Training Detail'!$M$5:$M$5000=Standards!A9)*('Training Detail'!$G$5:$G$5000>=D8)*('Training Detail'!$G$5:$G$5000<=E8)*('Training Detail'!$P$5:$P$5000))) -> 0 | N8: =IF(A8="","",IF(C8="","Set exp date",IF(AND(F8>=Requirements!B5,G8>=Requirements!B6,H8>=Requirements!B7,I8>=Requirements!B8,J8>=Requirements!B9,K8>=Requirements!B10,L8>=Requirements!B11,M8>=Requirements!B12),"Met","Short"))) -> Short | O8: =IF(OR(A8="",C8=""),"",IF(N8="Met","",IF(F8<Requirements!B5,Requirements!A5&" "&TEXT(Requirements!B5-F8,"0.##")&"; ","")&IF(G8<Requirements!B6,Requirements!A6&" "&TEXT(Requirements!B6-G8,"0.##")&"; ","")&IF(H8<Requirements!B7,Requirements!A7&" "&TEXT(Requirements!B7-H8,"0.##")&"; ","")&IF(I8<Requirements!B8,Requirements!A8&" "&TEXT(Requirements!B8-I8,"0.##")&"; ","")&IF(J8<Requirements!B9,Requirements!A9&" "&TEXT(Requirements!B9-J8,"0.##")&"; ","")&IF(K8<Requirements!B10,Requirements!A10&" "&TEXT(Requirements!B10-K8,"0.##")&"; ","")&IF(L8<Requirements!B11,Requirements!A11&" "&TEXT(Requirements!B11-L8,"0.##")&"; ","")&IF(M8<Requirements!B12,Requirements!A12&" "&TEXT(Requirements!B12-M8,"0.##")&"; ",""))) -> Airway 2; Cardiovascular 5; Trauma 0.5; Medical 1; Operations 1; CPR/AED 1;
A9: Adams, Jerry | B9: 1127358 | C9: 46752 | D9: =IF(C9="","",DATE(YEAR(C9)-1,1,1)) -> 46023 | E9: =IF(C9="","",DATE(YEAR(C9),12,31)) -> 46752 | F9: =IF(OR(A9="",C9=""),"",SUMPRODUCT(('Training Detail'!$A$5:$A$5000=A9)*('Training Detail'!$M$5:$M$5000=Standards!A2)*('Training Detail'!$G$5:$G$5000>=D9)*('Training Detail'!$G$5:$G$5000<=E9)*('Training Detail'!$P$5:$P$5000))) -> 0 | G9: =IF(OR(A9="",C9=""),"",SUMPRODUCT(('Training Detail'!$A$5:$A$5000=A9)*('Training Detail'!$M$5:$M$5000=Standards!A3)*('Training Detail'!$G$5:$G$5000>=D9)*('Training Detail'!$G$5:$G$5000<=E9)*('Training Detail'!$P$5:$P$5000))) -> 0 | H9: =IF(OR(A9="",C9=""),"",SUMPRODUCT(('Training Detail'!$A$5:$A$5000=A9)*('Training Detail'!$M$5:$M$5000=Standards!A4)*('Training Detail'!$G$5:$G$5000>=D9)*('Training Detail'!$G$5:$G$5000<=E9)*('Training Detail'!$P$5:$P$5000))) -> 2 | I9: =IF(OR(A9="",C9=""),"",SUMPRODUCT(('Training Detail'!$A$5:$A$5000=A9)*('Training Detail'!$M$5:$M$5000=Standards!A5)*('Training Detail'!$G$5:$G$5000>=D9)*('Training Detail'!$G$5:$G$5000<=E9)*('Training Detail'!$P$5:$P$5000))) -> 0 | J9: =IF(OR(A9="",C9=""),"",SUMPRODUCT(('Training Detail'!$A$5:$A$5000=A9)*('Training Detail'!$M$5:$M$5000=Standards!A6)*('Training Detail'!$G$5:$G$5000>=D9)*('Training Detail'!$G$5:$G$5000<=E9)*('Training Detail'!$P$5:$P$5000))) -> 1 | K9: =IF(OR(A9="",C9=""),"",SUMPRODUCT(('Training Detail'!$A$5:$A$5000=A9)*('Training Detail'!$M$5:$M$5000=Standards!A7)*('Training Detail'!$G$5:$G$5000>=D9)*('Training Detail'!$G$5:$G$5000<=E9)*('Training Detail'!$P$5:$P$5000))) -> 0 | L9: =IF(OR(A9="",C9=""),"",SUMPRODUCT(('Training Detail'!$A$5:$A$5000=A9)*('Training Detail'!$M$5:$M$5000=Standards!A8)*('Training Detail'!$G$5:$G$5000>=D9)*('Training Detail'!$G$5:$G$5000<=E9)*('Training Detail'!$P$5:$P$5000))) -> 0 | M9: =IF(OR(A9="",C9=""),"",SUMPRODUCT(('Training Detail'!$A$5:$A$5000=A9)*('Training Detail'!$M$5:$M$5000=Standards!A9)*('Training Detail'!$G$5:$G$5000>=D9)*('Training Detail'!$G$5:$G$5000<=E9)*('Training Detail'!$P$5:$P$5000))) -> 0 | N9: =IF(A9="","",IF(C9="","Set exp date",IF(AND(F9>=Requirements!B5,G9>=Requirements!B6,H9>=Requirements!B7,I9>=Requirements!B8,J9>=Requirements!B9,K9>=Requirements!B10,L9>=Requirements!B11,M9>=Requirements!B12),"Met","Short"))) -> Short | O9: =IF(OR(A9="",C9=""),"",IF(N9="Met","",IF(F9<Requirements!B5,Requirements!A5&" "&TEXT(Requirements!B5-F9,"0.##")&"; ","")&IF(G9<Requirements!B6,Requirements!A6&" "&TEXT(Requirements!B6-G9,"0.##")&"; ","")&IF(H9<Requirements!B7,Requirements!A7&" "&TEXT(Requirements!B7-H9,"0.##")&"; ","")&IF(I9<Requirements!B8,Requirements!A8&" "&TEXT(Requirements!B8-I9,"0.##")&"; ","")&IF(J9<Requirements!B9,Requirements!A9&" "&TEXT(Requirements!B9-J9,"0.##")&"; ","")&IF(K9<Requirements!B10,Requirements!A10&" "&TEXT(Requirements!B10-K9,"0.##")&"; ","")&IF(L9<Requirements!B11,Requirements!A11&" "&TEXT(Requirements!B11-L9,"0.##")&"; ","")&IF(M9<Requirements!B12,Requirements!A12&" "&TEXT(Requirements!B12-M9,"0.##")&"; ",""))) -> Airway 4; Cardiovascular 5; Trauma 1; Medical 6; Operations 1; PAHT 1; SVAT 1; CPR/AED 1;
A10: Akins, Brad | B10: 1055741 | C10: 46387 | D10: =IF(C10="","",DATE(YEAR(C10)-1,1,1)) -> 45658 | E10: =IF(C10="","",DATE(YEAR(C10),12,31)) -> 46387 | F10: =IF(OR(A10="",C10=""),"",SUMPRODUCT(('Training Detail'!$A$5:$A$5000=A10)*('Training Detail'!$M$5:$M$5000=Standards!A2)*('Training Detail'!$G$5:$G$5000>=D10)*('Training Detail'!$G$5:$G$5000<=E10)*('Training Detail'!$P$5:$P$5000))) -> 3 | G10: =IF(OR(A10="",C10=""),"",SUMPRODUCT(('Training Detail'!$A$5:$A$5000=A10)*('Training Detail'!$M$5:$M$5000=Standards!A3)*('Training Detail'!$G$5:$G$5000>=D10)*('Training Detail'!$G$5:$G$5000<=E10)*('Training Detail'!$P$5:$P$5000))) -> 2 | H10: =IF(OR(A10="",C10=""),"",SUMPRODUCT(('Training Detail'!$A$5:$A$5000=A10)*('Training Detail'!$M$5:$M$5000=Standards!A4)*('Training Detail'!$G$5:$G$5000>=D10)*('Training Detail'!$G$5:$G$5000<=E10)*('Training Detail'!$P$5:$P$5000))) -> 12 | I10: =IF(OR(A10="",C10=""),"",SUMPRODUCT(('Training Detail'!$A$5:$A$5000=A10)*('Training Detail'!$M$5:$M$5000=Standards!A5)*('Training Detail'!$G$5:$G$5000>=D10)*('Training Detail'!$G$5:$G$5000<=E10)*('Training Detail'!$P$5:$P$5000))) -> 3.5 | J10: =IF(OR(A10="",C10=""),"",SUMPRODUCT(('Training Detail'!$A$5:$A$5000=A10)*('Training Detail'!$M$5:$M$5000=Standards!A6)*('Training Detail'!$G$5:$G$5000>=D10)*('Training Detail'!$G$5:$G$5000<=E10)*('Training Detail'!$P$5:$P$5000))) -> 1 | K10: =IF(OR(A10="",C10=""),"",SUMPRODUCT(('Training Detail'!$A$5:$A$5000=A10)*('Training Detail'!$M$5:$M$5000=Standards!A7)*('Training Detail'!$G$5:$G$5000>=D10)*('Training Detail'!$G$5:$G$5000<=E10)*('Training Detail'!$P$5:$P$5000))) -> 1 | L10: =IF(OR(A10="",C10=""),"",SUMPRODUCT(('Training Detail'!$A$5:$A$5000=A10)*('Training Detail'!$M$5:$M$5000=Standards!A8)*('Training Detail'!$G$5:$G$5000>=D10)*('Training Detail'!$G$5:$G$5000<=E10)*('Training Detail'!$P$5:$P$5000))) -> 1 | M10: =IF(OR(A10="",C10=""),"",SUMPRODUCT(('Training Detail'!$A$5:$A$5000=A10)*('Training Detail'!$M$5:$M$5000=Standards!A9)*('Training Detail'!$G$5:$G$5000>=D10)*('Training Detail'!$G$5:$G$5000<=E10)*('Training Detail'!$P$5:$P$5000))) -> 0 | N10: =IF(A10="","",IF(C10="","Set exp date",IF(AND(F10>=Requirements!B5,G10>=Requirements!B6,H10>=Requirements!B7,I10>=Requirements!B8,J10>=Requirements!B9,K10>=Requirements!B10,L10>=Requirements!B11,M10>=Requirements!B12),"Met","Short"))) -> Short | O10: =IF(OR(A10="",C10=""),"",IF(N10="Met","",IF(F10<Requirements!B5,Requirements!A5&" "&TEXT(Requirements!B5-F10,"0.##")&"; ","")&IF(G10<Requirements!B6,Requirements!A6&" "&TEXT(Requirements!B6-G10,"0.##")&"; ","")&IF(H10<Requirements!B7,Requirements!A7&" "&TEXT(Requirements!B7-H10,"0.##")&"; ","")&IF(I10<Requirements!B8,Requirements!A8&" "&TEXT(Requirements!B8-I10,"0.##")&"; ","")&IF(J10<Requirements!B9,Requirements!A9&" "&TEXT(Requirements!B9-J10,"0.##")&"; ","")&IF(K10<Requirements!B10,Requirements!A10&" "&TEXT(Requirements!B10-K10,"0.##")&"; ","")&IF(L10<Requirements!B11,Requirements!A11&" "&TEXT(Requirements!B11-L10,"0.##")&"; ","")&IF(M10<Requirements!B12,Requirements!A12&" "&TEXT(Requirements!B12-M10,"0.##")&"; ",""))) -> Airway 1; Cardiovascular 3; Medical 2.5; Operations 1; CPR/AED 1;
A11: Alexander, Mike | B11: 1046585 | C11: 46752 | D11: =IF(C11="","",DATE(YEAR(C11)-1,1,1)) -> 46023 | E11: =IF(C11="","",DATE(YEAR(C11),12,31)) -> 46752 | F11: =IF(OR(A11="",C11=""),"",SUMPRODUCT(('Training Detail'!$A$5:$A$5000=A11)*('Training Detail'!$M$5:$M$5000=Standards!A2)*('Training Detail'!$G$5:$G$5000>=D11)*('Training Detail'!$G$5:$G$5000<=E11)*('Training Detail'!$P$5:$P$5000))) -> 0 | G11: =IF(OR(A11="",C11=""),"",SUMPRODUCT(('Training Detail'!$A$5:$A$5000=A11)*('Training Detail'!$M$5:$M$5000=Standards!A3)*('Training Detail'!$G$5:$G$5000>=D11)*('Training Detail'!$G$5:$G$5000<=E11)*('Training Detail'!$P$5:$P$5000))) -> 0 | H11: =IF(OR(A11="",C11=""),"",SUMPRODUCT(('Training Detail'!$A$5:$A$5000=A11)*('Training Detail'!$M$5:$M$5000=Standards!A4)*('Training Detail'!$G$5:$G$5000>=D11)*('Training Detail'!$G$5:$G$5000<=E11)*('Training Detail'!$P$5:$P$5000))) -> 0 | I11: =IF(OR(A11="",C11=""),"",SUMPRODUCT(('Training Detail'!$A$5:$A$5000=A11)*('Training Detail'!$M$5:$M$5000=Standards!A5)*('Training Detail'!$G$5:$G$5000>=D11)*('Training Detail'!$G$5:$G$5000<=E11)*('Training Detail'!$P$5:$P$5000))) -> 0 | J11: =IF(OR(A11="",C11=""),"",SUMPRODUCT(('Training Detail'!$A$5:$A$5000=A11)*('Training Detail'!$M$5:$M$5000=Standards!A6)*('Training Detail'!$G$5:$G$5000>=D11)*('Training Detail'!$G$5:$G$5000<=E11)*('Training Detail'!$P$5:$P$5000))) -> 0 | K11: =IF(OR(A11="",C11=""),"",SUMPRODUCT(('Training Detail'!$A$5:$A$5000=A11)*('Training Detail'!$M$5:$M$5000=Standards!A7)*('Training Detail'!$G$5:$G$5000>=D11)*('Training Detail'!$G$5:$G$5000<=E11)*('Training Detail'!$P$5:$P$5000))) -> 0 | L11: =IF(OR(A11="",C11=""),"",SUMPRODUCT(('Training Detail'!$A$5:$A$5000=A11)*('Training Detail'!$M$5:$M$5000=Standards!A8)*('Training Detail'!$G$5:$G$5000>=D11)*('Training Detail'!$G$5:$G$5000<=E11)*('Training Detail'!$P$5:$P$5000))) -> 0 | M11: =IF(OR(A11="",C11=""),"",SUMPRODUCT(('Training Detail'!$A$5:$A$5000=A11)*('Training Detail'!$M$5:$M$5000=Standards!A9)*('Training Detail'!$G$5:$G$5000>=D11)*('Training Detail'!$G$5:$G$5000<=E11)*('Training Detail'!$P$5:$P$5000))) -> 0 | N11: =IF(A11="","",IF(C11="","Set exp date",IF(AND(F11>=Requirements!B5,G11>=Requirements!B6,H11>=Requirements!B7,I11>=Requirements!B8,J11>=Requirements!B9,K11>=Requirements!B10,L11>=Requirements!B11,M11>=Requirements!B12),"Met","Short"))) -> Short | O11: =IF(OR(A11="",C11=""),"",IF(N11="Met","",IF(F11<Requirements!B5,Requirements!A5&" "&TEXT(Requirements!B5-F11,"0.##")&"; ","")&IF(G11<Requirements!B6,Requirements!A6&" "&TEXT(Requirements!B6-G11,"0.##")&"; ","")&IF(H11<Requirements!B7,Requirements!A7&" "&TEXT(Requirements!B7-H11,"0.##")&"; ","")&IF(I11<Requirements!B8,Requirements!A8&" "&TEXT(Requirements!B8-I11,"0.##")&"; ","")&IF(J11<Requirements!B9,Requirements!A9&" "&TEXT(Requirements!B9-J11,"0.##")&"; ","")&IF(K11<Requirements!B10,Requirements!A10&" "&TEXT(Requirements!B10-K11,"0.##")&"; ","")&IF(L11<Requirements!B11,Requirements!A11&" "&TEXT(Requirements!B11-L11,"0.##")&"; ","")&IF(M11<Requirements!B12,Requirements!A12&" "&TEXT(Requirements!B12-M11,"0.##")&"; ",""))) -> Airway 4; Cardiovascular 5; Trauma 3; Medical 6; Operations 2; PAHT 1; SVAT 1; CPR/AED 1;
A12: Anthony, Isaac | B12: 1050020 | C12: 46752 | D12: =IF(C12="","",DATE(YEAR(C12)-1,1,1)) -> 46023 | E12: =IF(C12="","",DATE(YEAR(C12),12,31)) -> 46752 | F12: =IF(OR(A12="",C12=""),"",SUMPRODUCT(('Training Detail'!$A$5:$A$5000=A12)*('Training Detail'!$M$5:$M$5000=Standards!A2)*('Training Detail'!$G$5:$G$5000>=D12)*('Training Detail'!$G$5:$G$5000<=E12)*('Training Detail'!$P$5:$P$5000))) -> 0 | G12: =IF(OR(A12="",C12=""),"",SUMPRODUCT(('Training Detail'!$A$5:$A$5000=A12)*('Training Detail'!$M$5:$M$5000=Standards!A3)*('Training Detail'!$G$5:$G$5000>=D12)*('Training Detail'!$G$5:$G$5000<=E12)*('Training Detail'!$P$5:$P$5000))) -> 0 | H12: =IF(OR(A12="",C12=""),"",SUMPRODUCT(('Training Detail'!$A$5:$A$5000=A12)*('Training Detail'!$M$5:$M$5000=Standards!A4)*('Training Detail'!$G$5:$G$5000>=D12)*('Training Detail'!$G$5:$G$5000<=E12)*('Training Detail'!$P$5:$P$5000))) -> 6.5 | I12: =IF(OR(A12="",C12=""),"",SUMPRODUCT(('Training Detail'!$A$5:$A$5000=A12)*('Training Detail'!$M$5:$M$5000=Standards!A5)*('Training Detail'!$G$5:$G$5000>=D12)*('Training Detail'!$G$5:$G$5000<=E12)*('Training Detail'!$P$5:$P$5000))) -> 1 | J12: =IF(OR(A12="",C12=""),"",SUMPRODUCT(('Training Detail'!$A$5:$A$5000=A12)*('Training Detail'!$M$5:$M$5000=Standards!A6)*('Training Detail'!$G$5:$G$5000>=D12)*('Training Detail'!$G$5:$G$5000<=E12)*('Training Detail'!$P$5:$P$5000))) -> 0 | K12: =IF(OR(A12="",C12=""),"",SUMPRODUCT(('Training Detail'!$A$5:$A$5000=A12)*('Training Detail'!$M$5:$M$5000=Standards!A7)*('Training Detail'!$G$5:$G$5000>=D12)*('Training Detail'!$G$5:$G$5000<=E12)*('Training Detail'!$P$5:$P$5000))) -> 0 | L12: =IF(OR(A12="",C12=""),"",SUMPRODUCT(('Training Detail'!$A$5:$A$5000=A12)*('Training Detail'!$M$5:$M$5000=Standards!A8)*('Training Detail'!$G$5:$G$5000>=D12)*('Training Detail'!$G$5:$G$5000<=E12)*('Training Detail'!$P$5:$P$5000))) -> 0 | M12: =IF(OR(A12="",C12=""),"",SUMPRODUCT(('Training Detail'!$A$5:$A$5000=A12)*('Training Detail'!$M$5:$M$5000=Standards!A9)*('Training Detail'!$G$5:$G$5000>=D12)*('Training Detail'!$G$5:$G$5000<=E12)*('Training Detail'!$P$5:$P$5000))) -> 0 | N12: =IF(A12="","",IF(C12="","Set exp date",IF(AND(F12>=Requirements!B5,G12>=Requirements!B6,H12>=Requirements!B7,I12>=Requirements!B8,J12>=Requirements!B9,K12>=Requirements!B10,L12>=Requirements!B11,M12>=Requirements!B12),"Met","Short"))) -> Short | O12: =IF(OR(A12="",C12=""),"",IF(N12="Met","",IF(F12<Requirements!B5,Requirements!A5&" "&TEXT(Requirements!B5-F12,"0.##")&"; ","")&IF(G12<Requirements!B6,Requirements!A6&" "&TEXT(Requirements!B6-G12,"0.##")&"; ","")&IF(H12<Requirements!B7,Requirements!A7&" "&TEXT(Requirements!B7-H12,"0.##")&"; ","")&IF(I12<Requirements!B8,Requirements!A8&" "&TEXT(Requirements!B8-I12,"0.##")&"; ","")&IF(J12<Requirements!B9,Requirements!A9&" "&TEXT(Requirements!B9-J12,"0.##")&"; ","")&IF(K12<Requirements!B10,Requirements!A10&" "&TEXT(Requirements!B10-K12,"0.##")&"; ","")&IF(L12<Requirements!B11,Requirements!A11&" "&TEXT(Requirements!B11-L12,"0.##")&"; ","")&IF(M12<Requirements!B12,Requirements!A12&" "&TEXT(Requirements!B12-M12,"0.##")&"; ",""))) -> Airway 4; Cardiovascular 5; Medical 5; Operations 2; PAHT 1; SVAT 1; CPR/AED 1;
A13: Anthony, Levi | B13: 1127964 | C13: 46752 | D13: =IF(C13="","",DATE(YEAR(C13)-1,1,1)) -> 46023 | E13: =IF(C13="","",DATE(YEAR(C13),12,31)) -> 46752 | F13: =IF(OR(A13="",C13=""),"",SUMPRODUCT(('Training Detail'!$A$5:$A$5000=A13)*('Training Detail'!$M$5:$M$5000=Standards!A2)*('Training Detail'!$G$5:$G$5000>=D13)*('Training Detail'!$G$5:$G$5000<=E13)*('Training Detail'!$P$5:$P$5000))) -> 1 | G13: =IF(OR(A13="",C13=""),"",SUMPRODUCT(('Training Detail'!$A$5:$A$5000=A13)*('Training Detail'!$M$5:$M$5000=Standards!A3)*('Training Detail'!$G$5:$G$5000>=D13)*('Training Detail'!$G$5:$G$5000<=E13)*('Training Detail'!$P$5:$P$5000))) -> 1 | H13: =IF(OR(A13="",C13=""),"",SUMPRODUCT(('Training Detail'!$A$5:$A$5000=A13)*('Training Detail'!$M$5:$M$5000=Standards!A4)*('Training Detail'!$G$5:$G$5000>=D13)*('Training Detail'!$G$5:$G$5000<=E13)*('Training Detail'!$P$5:$P$5000))) -> 4 | I13: =IF(OR(A13="",C13=""),"",SUMPRODUCT(('Training Detail'!$A$5:$A$5000=A13)*('Training Detail'!$M$5:$M$5000=Standards!A5)*('Training Detail'!$G$5:$G$5000>=D13)*('Training Detail'!$G$5:$G$5000<=E13)*('Training Detail'!$P$5:$P$5000))) -> 2 | J13: =IF(OR(A13="",C13=""),"",SUMPRODUCT(('Training Detail'!$A$5:$A$5000=A13)*('Training Detail'!$M$5:$M$5000=Standards!A6)*('Training Detail'!$G$5:$G$5000>=D13)*('Training Detail'!$G$5:$G$5000<=E13)*('Training Detail'!$P$5:$P$5000))) -> 2 | K13: =IF(OR(A13="",C13=""),"",SUMPRODUCT(('Training Detail'!$A$5:$A$5000=A13)*('Training Detail'!$M$5:$M$5000=Standards!A7)*('Training Detail'!$G$5:$G$5000>=D13)*('Training Detail'!$G$5:$G$5000<=E13)*('Training Detail'!$P$5:$P$5000))) -> 0 | L13: =IF(OR(A13="",C13=""),"",SUMPRODUCT(('Training Detail'!$A$5:$A$5000=A13)*('Training Detail'!$M$5:$M$5000=Standards!A8)*('Training Detail'!$G$5:$G$5000>=D13)*('Training Detail'!$G$5:$G$5000<=E13)*('Training Detail'!$P$5:$P$5000))) -> 0 | M13: =IF(OR(A13="",C13=""),"",SUMPRODUCT(('Training Detail'!$A$5:$A$5000=A13)*('Training Detail'!$M$5:$M$5000=Standards!A9)*('Training Detail'!$G$5:$G$5000>=D13)*('Training Detail'!$G$5:$G$5000<=E13)*('Training Detail'!$P$5:$P$5000))) -> 0 | N13: =IF(A13="","",IF(C13="","Set exp date",IF(AND(F13>=Requirements!B5,G13>=Requirements!B6,H13>=Requirements!B7,I13>=Requirements!B8,J13>=Requirements!B9,K13>=Requirements!B10,L13>=Requirements!B11,M13>=Requirements!B12),"Met","Short"))) -> Short | O13: =IF(OR(A13="",C13=""),"",IF(N13="Met","",IF(F13<Requirements!B5,Requirements!A5&" "&TEXT(Requirements!B5-F13,"0.##")&"; ","")&IF(G13<Requirements!B6,Requirements!A6&" "&TEXT(Requirements!B6-G13,"0.##")&"; ","")&IF(H13<Requirements!B7,Requirements!A7&" "&TEXT(Requirements!B7-H13,"0.##")&"; ","")&IF(I13<Requirements!B8,Requirements!A8&" "&TEXT(Requirements!B8-I13,"0.##")&"; ","")&IF(J13<Requirements!B9,Requirements!A9&" "&TEXT(Requirements!B9-J13,"0.##")&"; ","")&IF(K13<Requirements!B10,Requirements!A10&" "&TEXT(Requirements!B10-K13,"0.##")&"; ","")&IF(L13<Requirements!B11,Requirements!A11&" "&TEXT(Requirements!B11-L13,"0.##")&"; ","")&IF(M13<Requirements!B12,Requirements!A12&" "&TEXT(Requirements!B12-M13,"0.##")&"; ",""))) -> Airway 3; Cardiovascular 4; Medical 4; PAHT 1; SVAT 1; CPR/AED 1;
A14: Ashley, Daniel | B14: 1051669 | C14: 46387 | D14: =IF(C14="","",DATE(YEAR(C14)-1,1,1)) -> 45658 | E14: =IF(C14="","",DATE(YEAR(C14),12,31)) -> 46387 | F14: =IF(OR(A14="",C14=""),"",SUMPRODUCT(('Training Detail'!$A$5:$A$5000=A14)*('Training Detail'!$M$5:$M$5000=Standards!A2)*('Training Detail'!$G$5:$G$5000>=D14)*('Training Detail'!$G$5:$G$5000<=E14)*('Training Detail'!$P$5:$P$5000))) -> 0 | G14: =IF(OR(A14="",C14=""),"",SUMPRODUCT(('Training Detail'!$A$5:$A$5000=A14)*('Training Detail'!$M$5:$M$5000=Standards!A3)*('Training Detail'!$G$5:$G$5000>=D14)*('Training Detail'!$G$5:$G$5000<=E14)*('Training Detail'!$P$5:$P$5000))) -> 0 | H14: =IF(OR(A14="",C14=""),"",SUMPRODUCT(('Training Detail'!$A$5:$A$5000=A14)*('Training Detail'!$M$5:$M$5000=Standards!A4)*('Training Detail'!$G$5:$G$5000>=D14)*('Training Detail'!$G$5:$G$5000<=E14)*('Training Detail'!$P$5:$P$5000))) -> 16 | I14: =IF(OR(A14="",C14=""),"",SUMPRODUCT(('Training Detail'!$A$5:$A$5000=A14)*('Training Detail'!$M$5:$M$5000=Standards!A5)*('Training Detail'!$G$5:$G$5000>=D14)*('Training Detail'!$G$5:$G$5000<=E14)*('Training Detail'!$P$5:$P$5000))) -> 2 | J14: =IF(OR(A14="",C14=""),"",SUMPRODUCT(('Training Detail'!$A$5:$A$5000=A14)*('Training Detail'!$M$5:$M$5000=Standards!A6)*('Training Detail'!$G$5:$G$5000>=D14)*('Training Detail'!$G$5:$G$5000<=E14)*('Training Detail'!$P$5:$P$5000))) -> 3.5 | K14: =IF(OR(A14="",C14=""),"",SUMPRODUCT(('Training Detail'!$A$5:$A$5000=A14)*('Training Detail'!$M$5:$M$5000=Standards!A7)*('Training Detail'!$G$5:$G$5000>=D14)*('Training Detail'!$G$5:$G$5000<=E14)*('Training Detail'!$P$5:$P$5000))) -> 0 | L14: =IF(OR(A14="",C14=""),"",SUMPRODUCT(('Training Detail'!$A$5:$A$5000=A14)*('Training Detail'!$M$5:$M$5000=Standards!A8)*('Training Detail'!$G$5:$G$5000>=D14)*('Training Detail'!$G$5:$G$5000<=E14)*('Training Detail'!$P$5:$P$5000))) -> 0 | M14: =IF(OR(A14="",C14=""),"",SUMPRODUCT(('Training Detail'!$A$5:$A$5000=A14)*('Training Detail'!$M$5:$M$5000=Standards!A9)*('Training Detail'!$G$5:$G$5000>=D14)*('Training Detail'!$G$5:$G$5000<=E14)*('Training Detail'!$P$5:$P$5000))) -> 2 | N14: =IF(A14="","",IF(C14="","Set exp date",IF(AND(F14>=Requirements!B5,G14>=Requirements!B6,H14>=Requirements!B7,I14>=Requirements!B8,J14>=Requirements!B9,K14>=Requirements!B10,L14>=Requirements!B11,M14>=Requirements!B12),"Met","Short"))) -> Short | O14: =IF(OR(A14="",C14=""),"",IF(N14="Met","",IF(F14<Requirements!B5,Requirements!A5&" "&TEXT(Requirements!B5-F14,"0.##")&"; ","")&IF(G14<Requirements!B6,Requirements!A6&" "&TEXT(Requirements!B6-G14,"0.##")&"; ","")&IF(H14<Requirements!B7,Requirements!A7&" "&TEXT(Requirements!B7-H14,"0.##")&"; ","")&IF(I14<Requirements!B8,Requirements!A8&" "&TEXT(Requirements!B8-I14,"0.##")&"; ","")&IF(J14<Requirements!B9,Requirements!A9&" "&TEXT(Requirements!B9-J14,"0.##")&"; ","")&IF(K14<Requirements!B10,Requirements!A10&" "&TEXT(Requirements!B10-K14,"0.##")&"; ","")&IF(L14<Requirements!B11,Requirements!A11&" "&TEXT(Requirements!B11-L14,"0.##")&"; ","")&IF(M14<Requirements!B12,Requirements!A12&" "&TEXT(Requirements!B12-M14,"0.##")&"; ",""))) -> Airway 4; Cardiovascular 5; Medical 4; PAHT 1; SVAT 1;
A15: Atkins, Nick | B15: 1123453 | C15: 46752 | D15: =IF(C15="","",DATE(YEAR(C15)-1,1,1)) -> 46023 | E15: =IF(C15="","",DATE(YEAR(C15),12,31)) -> 46752 | F15: =IF(OR(A15="",C15=""),"",SUMPRODUCT(('Training Detail'!$A$5:$A$5000=A15)*('Training Detail'!$M$5:$M$5000=Standards!A2)*('Training Detail'!$G$5:$G$5000>=D15)*('Training Detail'!$G$5:$G$5000<=E15)*('Training Detail'!$P$5:$P$5000))) -> 0 | G15: =IF(OR(A15="",C15=""),"",SUMPRODUCT(('Training Detail'!$A$5:$A$5000=A15)*('Training Detail'!$M$5:$M$5000=Standards!A3)*('Training Detail'!$G$5:$G$5000>=D15)*('Training Detail'!$G$5:$G$5000<=E15)*('Training Detail'!$P$5:$P$5000))) -> 0 | H15: =IF(OR(A15="",C15=""),"",SUMPRODUCT(('Training Detail'!$A$5:$A$5000=A15)*('Training Detail'!$M$5:$M$5000=Standards!A4)*('Training Detail'!$G$5:$G$5000>=D15)*('Training Detail'!$G$5:$G$5000<=E15)*('Training Detail'!$P$5:$P$5000))) -> 26 | I15: =IF(OR(A15="",C15=""),"",SUMPRODUCT(('Training Detail'!$A$5:$A$5000=A15)*('Training Detail'!$M$5:$M$5000=Standards!A5)*('Training Detail'!$G$5:$G$5000>=D15)*('Training Detail'!$G$5:$G$5000<=E15)*('Training Detail'!$P$5:$P$5000))) -> 0.5 | J15: =IF(OR(A15="",C15=""),"",SUMPRODUCT(('Training Detail'!$A$5:$A$5000=A15)*('Training Detail'!$M$5:$M$5000=Standards!A6)*('Training Detail'!$G$5:$G$5000>=D15)*('Training Detail'!$G$5:$G$5000<=E15)*('Training Detail'!$P$5:$P$5000))) -> 14 | K15: =IF(OR(A15="",C15=""),"",SUMPRODUCT(('Training Detail'!$A$5:$A$5000=A15)*('Training Detail'!$M$5:$M$5000=Standards!A7)*('Training Detail'!$G$5:$G$5000>=D15)*('Training Detail'!$G$5:$G$5000<=E15)*('Training Detail'!$P$5:$P$5000))) -> 0 | L15: =IF(OR(A15="",C15=""),"",SUMPRODUCT(('Training Detail'!$A$5:$A$5000=A15)*('Training Detail'!$M$5:$M$5000=Standards!A8)*('Training Detail'!$G$5:$G$5000>=D15)*('Training Detail'!$G$5:$G$5000<=E15)*('Training Detail'!$P$5:$P$5000))) -> 0 | M15: =IF(OR(A15="",C15=""),"",SUMPRODUCT(('Training Detail'!$A$5:$A$5000=A15)*('Training Detail'!$M$5:$M$5000=Standards!A9)*('Training Detail'!$G$5:$G$5000>=D15)*('Training Detail'!$G$5:$G$5000<=E15)*('Training Detail'!$P$5:$P$5000))) -> 1 | N15: =IF(A15="","",IF(C15="","Set exp date",IF(AND(F15>=Requirements!B5,G15>=Requirements!B6,H15>=Requirements!B7,I15>=Requirements!B8,J15>=Requirements!B9,K15>=Requirements!B10,L15>=Requirements!B11,M15>=Requirements!B12),"Met","Short"))) -> Short | O15: =IF(OR(A15="",C15=""),"",IF(N15="Met","",IF(F15<Requirements!B5,Requirements!A5&" "&TEXT(Requirements!B5-F15,"0.##")&"; ","")&IF(G15<Requirements!B6,Requirements!A6&" "&TEXT(Requirements!B6-G15,"0.##")&"; ","")&IF(H15<Requirements!B7,Requirements!A7&" "&TEXT(Requirements!B7-H15,"0.##")&"; ","")&IF(I15<Requirements!B8,Requirements!A8&" "&TEXT(Requirements!B8-I15,"0.##")&"; ","")&IF(J15<Requirements!B9,Requirements!A9&" "&TEXT(Requirements!B9-J15,"0.##")&"; ","")&IF(K15<Requirements!B10,Requirements!A10&" "&TEXT(Requirements!B10-K15,"0.##")&"; ","")&IF(L15<Requirements!B11,Requirements!A11&" "&TEXT(Requirements!B11-L15,"0.##")&"; ","")&IF(M15<Requirements!B12,Requirements!A12&" "&TEXT(Requirements!B12-M15,"0.##")&"; ",""))) -> Airway 4; Cardiovascular 5; Medical 5.5; PAHT 1; SVAT 1;
A16: Atkins, Ronnie | D16: =IF(C16="","",DATE(YEAR(C16)-1,1,1)) | E16: =IF(C16="","",DATE(YEAR(C16),12,31)) | F16: =IF(OR(A16="",C16=""),"",SUMPRODUCT(('Training Detail'!$A$5:$A$5000=A16)*('Training Detail'!$M$5:$M$5000=Standards!A2)*('Training Detail'!$G$5:$G$5000>=D16)*('Training Detail'!$G$5:$G$5000<=E16)*('Training Detail'!$P$5:$P$5000))) | G16: =IF(OR(A16="",C16=""),"",SUMPRODUCT(('Training Detail'!$A$5:$A$5000=A16)*('Training Detail'!$M$5:$M$5000=Standards!A3)*('Training Detail'!$G$5:$G$5000>=D16)*('Training Detail'!$G$5:$G$5000<=E16)*('Training Detail'!$P$5:$P$5000))) | H16: =IF(OR(A16="",C16=""),"",SUMPRODUCT(('Training Detail'!$A$5:$A$5000=A16)*('Training Detail'!$M$5:$M$5000=Standards!A4)*('Training Detail'!$G$5:$G$5000>=D16)*('Training Detail'!$G$5:$G$5000<=E16)*('Training Detail'!$P$5:$P$5000))) | I16: =IF(OR(A16="",C16=""),"",SUMPRODUCT(('Training Detail'!$A$5:$A$5000=A16)*('Training Detail'!$M$5:$M$5000=Standards!A5)*('Training Detail'!$G$5:$G$5000>=D16)*('Training Detail'!$G$5:$G$5000<=E16)*('Training Detail'!$P$5:$P$5000))) | J16: =IF(OR(A16="",C16=""),"",SUMPRODUCT(('Training Detail'!$A$5:$A$5000=A16)*('Training Detail'!$M$5:$M$5000=Standards!A6)*('Training Detail'!$G$5:$G$5000>=D16)*('Training Detail'!$G$5:$G$5000<=E16)*('Training Detail'!$P$5:$P$5000))) | K16: =IF(OR(A16="",C16=""),"",SUMPRODUCT(('Training Detail'!$A$5:$A$5000=A16)*('Training Detail'!$M$5:$M$5000=Standards!A7)*('Training Detail'!$G$5:$G$5000>=D16)*('Training Detail'!$G$5:$G$5000<=E16)*('Training Detail'!$P$5:$P$5000))) | L16: =IF(OR(A16="",C16=""),"",SUMPRODUCT(('Training Detail'!$A$5:$A$5000=A16)*('Training Detail'!$M$5:$M$5000=Standards!A8)*('Training Detail'!$G$5:$G$5000>=D16)*('Training Detail'!$G$5:$G$5000<=E16)*('Training Detail'!$P$5:$P$5000))) | M16: =IF(OR(A16="",C16=""),"",SUMPRODUCT(('Training Detail'!$A$5:$A$5000=A16)*('Training Detail'!$M$5:$M$5000=Standards!A9)*('Training Detail'!$G$5:$G$5000>=D16)*('Training Detail'!$G$5:$G$5000<=E16)*('Training Detail'!$P$5:$P$5000))) | N16: =IF(A16="","",IF(C16="","Set exp date",IF(AND(F16>=Requirements!B5,G16>=Requirements!B6,H16>=Requirements!B7,I16>=Requirements!B8,J16>=Requirements!B9,K16>=Requirements!B10,L16>=Requirements!B11,M16>=Requirements!B12),"Met","Short"))) -> Set exp date | O16: =IF(OR(A16="",C16=""),"",IF(N16="Met","",IF(F16<Requirements!B5,Requirements!A5&" "&TEXT(Requirements!B5-F16,"0.##")&"; ","")&IF(G16<Requirements!B6,Requirements!A6&" "&TEXT(Requirements!B6-G16,"0.##")&"; ","")&IF(H16<Requirements!B7,Requirements!A7&" "&TEXT(Requirements!B7-H16,"0.##")&"; ","")&IF(I16<Requirements!B8,Requirements!A8&" "&TEXT(Requirements!B8-I16,"0.##")&"; ","")&IF(J16<Requirements!B9,Requirements!A9&" "&TEXT(Requirements!B9-J16,"0.##")&"; ","")&IF(K16<Requirements!B10,Requirements!A10&" "&TEXT(Requirements!B10-K16,"0.##")&"; ","")&IF(L16<Requirements!B11,Requirements!A11&" "&TEXT(Requirements!B11-L16,"0.##")&"; ","")&IF(M16<Requirements!B12,Requirements!A12&" "&TEXT(Requirements!B12-M16,"0.##")&"; ","")))
A17: Ballance, John | D17: =IF(C17="","",DATE(YEAR(C17)-1,1,1)) | E17: =IF(C17="","",DATE(YEAR(C17),12,31)) | F17: =IF(OR(A17="",C17=""),"",SUMPRODUCT(('Training Detail'!$A$5:$A$5000=A17)*('Training Detail'!$M$5:$M$5000=Standards!A2)*('Training Detail'!$G$5:$G$5000>=D17)*('Training Detail'!$G$5:$G$5000<=E17)*('Training Detail'!$P$5:$P$5000))) | G17: =IF(OR(A17="",C17=""),"",SUMPRODUCT(('Training Detail'!$A$5:$A$5000=A17)*('Training Detail'!$M$5:$M$5000=Standards!A3)*('Training Detail'!$G$5:$G$5000>=D17)*('Training Detail'!$G$5:$G$5000<=E17)*('Training Detail'!$P$5:$P$5000))) | H17: =IF(OR(A17="",C17=""),"",SUMPRODUCT(('Training Detail'!$A$5:$A$5000=A17)*('Training Detail'!$M$5:$M$5000=Standards!A4)*('Training Detail'!$G$5:$G$5000>=D17)*('Training Detail'!$G$5:$G$5000<=E17)*('Training Detail'!$P$5:$P$5000))) | I17: =IF(OR(A17="",C17=""),"",SUMPRODUCT(('Training Detail'!$A$5:$A$5000=A17)*('Training Detail'!$M$5:$M$5000=Standards!A5)*('Training Detail'!$G$5:$G$5000>=D17)*('Training Detail'!$G$5:$G$5000<=E17)*('Training Detail'!$P$5:$P$5000))) | J17: =IF(OR(A17="",C17=""),"",SUMPRODUCT(('Training Detail'!$A$5:$A$5000=A17)*('Training Detail'!$M$5:$M$5000=Standards!A6)*('Training Detail'!$G$5:$G$5000>=D17)*('Training Detail'!$G$5:$G$5000<=E17)*('Training Detail'!$P$5:$P$5000))) | K17: =IF(OR(A17="",C17=""),"",SUMPRODUCT(('Training Detail'!$A$5:$A$5000=A17)*('Training Detail'!$M$5:$M$5000=Standards!A7)*('Training Detail'!$G$5:$G$5000>=D17)*('Training Detail'!$G$5:$G$5000<=E17)*('Training Detail'!$P$5:$P$5000))) | L17: =IF(OR(A17="",C17=""),"",SUMPRODUCT(('Training Detail'!$A$5:$A$5000=A17)*('Training Detail'!$M$5:$M$5000=Standards!A8)*('Training Detail'!$G$5:$G$5000>=D17)*('Training Detail'!$G$5:$G$5000<=E17)*('Training Detail'!$P$5:$P$5000))) | M17: =IF(OR(A17="",C17=""),"",SUMPRODUCT(('Training Detail'!$A$5:$A$5000=A17)*('Training Detail'!$M$5:$M$5000=Standards!A9)*('Training Detail'!$G$5:$G$5000>=D17)*('Training Detail'!$G$5:$G$5000<=E17)*('Training Detail'!$P$5:$P$5000))) | N17: =IF(A17="","",IF(C17="","Set exp date",IF(AND(F17>=Requirements!B5,G17>=Requirements!B6,H17>=Requirements!B7,I17>=Requirements!B8,J17>=Requirements!B9,K17>=Requirements!B10,L17>=Requirements!B11,M17>=Requirements!B12),"Met","Short"))) -> Set exp date | O17: =IF(OR(A17="",C17=""),"",IF(N17="Met","",IF(F17<Requirements!B5,Requirements!A5&" "&TEXT(Requirements!B5-F17,"0.##")&"; ","")&IF(G17<Requirements!B6,Requirements!A6&" "&TEXT(Requirements!B6-G17,"0.##")&"; ","")&IF(H17<Requirements!B7,Requirements!A7&" "&TEXT(Requirements!B7-H17,"0.##")&"; ","")&IF(I17<Requirements!B8,Requirements!A8&" "&TEXT(Requirements!B8-I17,"0.##")&"; ","")&IF(J17<Requirements!B9,Requirements!A9&" "&TEXT(Requirements!B9-J17,"0.##")&"; ","")&IF(K17<Requirements!B10,Requirements!A10&" "&TEXT(Requirements!B10-K17,"0.##")&"; ","")&IF(L17<Requirements!B11,Requirements!A11&" "&TEXT(Requirements!B11-L17,"0.##")&"; ","")&IF(M17<Requirements!B12,Requirements!A12&" "&TEXT(Requirements!B12-M17,"0.##")&"; ","")))
A18: Barnhart, Zach | B18: 1121401 | C18: 46752 | D18: =IF(C18="","",DATE(YEAR(C18)-1,1,1)) -> 46023 | E18: =IF(C18="","",DATE(YEAR(C18),12,31)) -> 46752 | F18: =IF(OR(A18="",C18=""),"",SUMPRODUCT(('Training Detail'!$A$5:$A$5000=A18)*('Training Detail'!$M$5:$M$5000=Standards!A2)*('Training Detail'!$G$5:$G$5000>=D18)*('Training Detail'!$G$5:$G$5000<=E18)*('Training Detail'!$P$5:$P$5000))) -> 0 | G18: =IF(OR(A18="",C18=""),"",SUMPRODUCT(('Training Detail'!$A$5:$A$5000=A18)*('Training Detail'!$M$5:$M$5000=Standards!A3)*('Training Detail'!$G$5:$G$5000>=D18)*('Training Detail'!$G$5:$G$5000<=E18)*('Training Detail'!$P$5:$P$5000))) -> 0 | H18: =IF(OR(A18="",C18=""),"",SUMPRODUCT(('Training Detail'!$A$5:$A$5000=A18)*('Training Detail'!$M$5:$M$5000=Standards!A4)*('Training Detail'!$G$5:$G$5000>=D18)*('Training Detail'!$G$5:$G$5000<=E18)*('Training Detail'!$P$5:$P$5000))) -> 4 | I18: =IF(OR(A18="",C18=""),"",SUMPRODUCT(('Training Detail'!$A$5:$A$5000=A18)*('Training Detail'!$M$5:$M$5000=Standards!A5)*('Training Detail'!$G$5:$G$5000>=D18)*('Training Detail'!$G$5:$G$5000<=E18)*('Training Detail'!$P$5:$P$5000))) -> 0 | J18: =IF(OR(A18="",C18=""),"",SUMPRODUCT(('Training Detail'!$A$5:$A$5000=A18)*('Training Detail'!$M$5:$M$5000=Standards!A6)*('Training Detail'!$G$5:$G$5000>=D18)*('Training Detail'!$G$5:$G$5000<=E18)*('Training Detail'!$P$5:$P$5000))) -> 1 | K18: =IF(OR(A18="",C18=""),"",SUMPRODUCT(('Training Detail'!$A$5:$A$5000=A18)*('Training Detail'!$M$5:$M$5000=Standards!A7)*('Training Detail'!$G$5:$G$5000>=D18)*('Training Detail'!$G$5:$G$5000<=E18)*('Training Detail'!$P$5:$P$5000))) -> 0 | L18: =IF(OR(A18="",C18=""),"",SUMPRODUCT(('Training Detail'!$A$5:$A$5000=A18)*('Training Detail'!$M$5:$M$5000=Standards!A8)*('Training Detail'!$G$5:$G$5000>=D18)*('Training Detail'!$G$5:$G$5000<=E18)*('Training Detail'!$P$5:$P$5000))) -> 0 | M18: =IF(OR(A18="",C18=""),"",SUMPRODUCT(('Training Detail'!$A$5:$A$5000=A18)*('Training Detail'!$M$5:$M$5000=Standards!A9)*('Training Detail'!$G$5:$G$5000>=D18)*('Training Detail'!$G$5:$G$5000<=E18)*('Training Detail'!$P$5:$P$5000))) -> 0 | N18: =IF(A18="","",IF(C18="","Set exp date",IF(AND(F18>=Requirements!B5,G18>=Requirements!B6,H18>=Requirements!B7,I18>=Requirements!B8,J18>=Requirements!B9,K18>=Requirements!B10,L18>=Requirements!B11,M18>=Requirements!B12),"Met","Short"))) -> Short | O18: =IF(OR(A18="",C18=""),"",IF(N18="Met","",IF(F18<Requirements!B5,Requirements!A5&" "&TEXT(Requirements!B5-F18,"0.##")&"; ","")&IF(G18<Requirements!B6,Requirements!A6&" "&TEXT(Requirements!B6-G18,"0.##")&"; ","")&IF(H18<Requirements!B7,Requirements!A7&" "&TEXT(Requirements!B7-H18,"0.##")&"; ","")&IF(I18<Requirements!B8,Requirements!A8&" "&TEXT(Requirements!B8-I18,"0.##")&"; ","")&IF(J18<Requirements!B9,Requirements!A9&" "&TEXT(Requirements!B9-J18,"0.##")&"; ","")&IF(K18<Requirements!B10,Requirements!A10&" "&TEXT(Requirements!B10-K18,"0.##")&"; ","")&IF(L18<Requirements!B11,Requirements!A11&" "&TEXT(Requirements!B11-L18,"0.##")&"; ","")&IF(M18<Requirements!B12,Requirements!A12&" "&TEXT(Requirements!B12-M18,"0.##")&"; ",""))) -> Airway 4; Cardiovascular 5; Medical 6; Operations 1; PAHT 1; SVAT 1; CPR/AED 1;
A19: Barrick, Ayden | B19: 1128971 | C19: 46387 | D19: =IF(C19="","",DATE(YEAR(C19)-1,1,1)) -> 45658 | E19: =IF(C19="","",DATE(YEAR(C19),12,31)) -> 46387 | F19: =IF(OR(A19="",C19=""),"",SUMPRODUCT(('Training Detail'!$A$5:$A$5000=A19)*('Training Detail'!$M$5:$M$5000=Standards!A2)*('Training Detail'!$G$5:$G$5000>=D19)*('Training Detail'!$G$5:$G$5000<=E19)*('Training Detail'!$P$5:$P$5000))) -> 1 | G19: =IF(OR(A19="",C19=""),"",SUMPRODUCT(('Training Detail'!$A$5:$A$5000=A19)*('Training Detail'!$M$5:$M$5000=Standards!A3)*('Training Detail'!$G$5:$G$5000>=D19)*('Training Detail'!$G$5:$G$5000<=E19)*('Training Detail'!$P$5:$P$5000))) -> 3.5 | H19: =IF(OR(A19="",C19=""),"",SUMPRODUCT(('Training Detail'!$A$5:$A$5000=A19)*('Training Detail'!$M$5:$M$5000=Standards!A4)*('Training Detail'!$G$5:$G$5000>=D19)*('Training Detail'!$G$5:$G$5000<=E19)*('Training Detail'!$P$5:$P$5000))) -> 4.5 | I19: =IF(OR(A19="",C19=""),"",SUMPRODUCT(('Training Detail'!$A$5:$A$5000=A19)*('Training Detail'!$M$5:$M$5000=Standards!A5)*('Training Detail'!$G$5:$G$5000>=D19)*('Training Detail'!$G$5:$G$5000<=E19)*('Training Detail'!$P$5:$P$5000))) -> 10.5 | J19: =IF(OR(A19="",C19=""),"",SUMPRODUCT(('Training Detail'!$A$5:$A$5000=A19)*('Training Detail'!$M$5:$M$5000=Standards!A6)*('Training Detail'!$G$5:$G$5000>=D19)*('Training Detail'!$G$5:$G$5000<=E19)*('Training Detail'!$P$5:$P$5000))) -> 2 | K19: =IF(OR(A19="",C19=""),"",SUMPRODUCT(('Training Detail'!$A$5:$A$5000=A19)*('Training Detail'!$M$5:$M$5000=Standards!A7)*('Training Detail'!$G$5:$G$5000>=D19)*('Training Detail'!$G$5:$G$5000<=E19)*('Training Detail'!$P$5:$P$5000))) -> 0 | L19: =IF(OR(A19="",C19=""),"",SUMPRODUCT(('Training Detail'!$A$5:$A$5000=A19)*('Training Detail'!$M$5:$M$5000=Standards!A8)*('Training Detail'!$G$5:$G$5000>=D19)*('Training Detail'!$G$5:$G$5000<=E19)*('Training Detail'!$P$5:$P$5000))) -> 0 | M19: =IF(OR(A19="",C19=""),"",SUMPRODUCT(('Training Detail'!$A$5:$A$5000=A19)*('Training Detail'!$M$5:$M$5000=Standards!A9)*('Training Detail'!$G$5:$G$5000>=D19)*('Training Detail'!$G$5:$G$5000<=E19)*('Training Detail'!$P$5:$P$5000))) -> 0.5 | N19: =IF(A19="","",IF(C19="","Set exp date",IF(AND(F19>=Requirements!B5,G19>=Requirements!B6,H19>=Requirements!B7,I19>=Requirements!B8,J19>=Requirements!B9,K19>=Requirements!B10,L19>=Requirements!B11,M19>=Requirements!B12),"Met","Short"))) -> Short | O19: =IF(OR(A19="",C19=""),"",IF(N19="Met","",IF(F19<Requirements!B5,Requirements!A5&" "&TEXT(Requirements!B5-F19,"0.##")&"; ","")&IF(G19<Requirements!B6,Requirements!A6&" "&TEXT(Requirements!B6-G19,"0.##")&"; ","")&IF(H19<Requirements!B7,Requirements!A7&" "&TEXT(Requirements!B7-H19,"0.##")&"; ","")&IF(I19<Requirements!B8,Requirements!A8&" "&TEXT(Requirements!B8-I19,"0.##")&"; ","")&IF(J19<Requirements!B9,Requirements!A9&" "&TEXT(Requirements!B9-J19,"0.##")&"; ","")&IF(K19<Requirements!B10,Requirements!A10&" "&TEXT(Requirements!B10-K19,"0.##")&"; ","")&IF(L19<Requirements!B11,Requirements!A11&" "&TEXT(Requirements!B11-L19,"0.##")&"; ","")&IF(M19<Requirements!B12,Requirements!A12&" "&TEXT(Requirements!B12-M19,"0.##")&"; ",""))) -> Airway 3; Cardiovascular 1.5; PAHT 1; SVAT 1; CPR/AED 0.5;
A20: Bates, Christopher | B20: 1117055 | C20: 46387 | D20: =IF(C20="","",DATE(YEAR(C20)-1,1,1)) -> 45658 | E20: =IF(C20="","",DATE(YEAR(C20),12,31)) -> 46387 | F20: =IF(OR(A20="",C20=""),"",SUMPRODUCT(('Training Detail'!$A$5:$A$5000=A20)*('Training Detail'!$M$5:$M$5000=Standards!A2)*('Training Detail'!$G$5:$G$5000>=D20)*('Training Detail'!$G$5:$G$5000<=E20)*('Training Detail'!$P$5:$P$5000))) -> 4 | G20: =IF(OR(A20="",C20=""),"",SUMPRODUCT(('Training Detail'!$A$5:$A$5000=A20)*('Training Detail'!$M$5:$M$5000=Standards!A3)*('Training Detail'!$G$5:$G$5000>=D20)*('Training Detail'!$G$5:$G$5000<=E20)*('Training Detail'!$P$5:$P$5000))) -> 5 | H20: =IF(OR(A20="",C20=""),"",SUMPRODUCT(('Training Detail'!$A$5:$A$5000=A20)*('Training Detail'!$M$5:$M$5000=Standards!A4)*('Training Detail'!$G$5:$G$5000>=D20)*('Training Detail'!$G$5:$G$5000<=E20)*('Training Detail'!$P$5:$P$5000))) -> 39.5 | I20: =IF(OR(A20="",C20=""),"",SUMPRODUCT(('Training Detail'!$A$5:$A$5000=A20)*('Training Detail'!$M$5:$M$5000=Standards!A5)*('Training Detail'!$G$5:$G$5000>=D20)*('Training Detail'!$G$5:$G$5000<=E20)*('Training Detail'!$P$5:$P$5000))) -> 7 | J20: =IF(OR(A20="",C20=""),"",SUMPRODUCT(('Training Detail'!$A$5:$A$5000=A20)*('Training Detail'!$M$5:$M$5000=Standards!A6)*('Training Detail'!$G$5:$G$5000>=D20)*('Training Detail'!$G$5:$G$5000<=E20)*('Training Detail'!$P$5:$P$5000))) -> 19 | K20: =IF(OR(A20="",C20=""),"",SUMPRODUCT(('Training Detail'!$A$5:$A$5000=A20)*('Training Detail'!$M$5:$M$5000=Standards!A7)*('Training Detail'!$G$5:$G$5000>=D20)*('Training Detail'!$G$5:$G$5000<=E20)*('Training Detail'!$P$5:$P$5000))) -> 1 | L20: =IF(OR(A20="",C20=""),"",SUMPRODUCT(('Training Detail'!$A$5:$A$5000=A20)*('Training Detail'!$M$5:$M$5000=Standards!A8)*('Training Detail'!$G$5:$G$5000>=D20)*('Training Detail'!$G$5:$G$5000<=E20)*('Training Detail'!$P$5:$P$5000))) -> 1 | M20: =IF(OR(A20="",C20=""),"",SUMPRODUCT(('Training Detail'!$A$5:$A$5000=A20)*('Training Detail'!$M$5:$M$5000=Standards!A9)*('Training Detail'!$G$5:$G$5000>=D20)*('Training Detail'!$G$5:$G$5000<=E20)*('Training Detail'!$P$5:$P$5000))) -> 0.5 | N20: =IF(A20="","",IF(C20="","Set exp date",IF(AND(F20>=Requirements!B5,G20>=Requirements!B6,H20>=Requirements!B7,I20>=Requirements!B8,J20>=Requirements!B9,K20>=Requirements!B10,L20>=Requirements!B11,M20>=Requirements!B12),"Met","Short"))) -> Short | O20: =IF(OR(A20="",C20=""),"",IF(N20="Met","",IF(F20<Requirements!B5,Requirements!A5&" "&TEXT(Requirements!B5-F20,"0.##")&"; ","")&IF(G20<Requirements!B6,Requirements!A6&" "&TEXT(Requirements!B6-G20,"0.##")&"; ","")&IF(H20<Requirements!B7,Requirements!A7&" "&TEXT(Requirements!B7-H20,"0.##")&"; ","")&IF(I20<Requirements!B8,Requirements!A8&" "&TEXT(Requirements!B8-I20,"0.##")&"; ","")&IF(J20<Requirements!B9,Requirements!A9&" "&TEXT(Requirements!B9-J20,"0.##")&"; ","")&IF(K20<Requirements!B10,Requirements!A10&" "&TEXT(Requirements!B10-K20,"0.##")&"; ","")&IF(L20<Requirements!B11,Requirements!A11&" "&TEXT(Requirements!B11-L20,"0.##")&"; ","")&IF(M20<Requirements!B12,Requirements!A12&" "&TEXT(Requirements!B12-M20,"0.##")&"; ",""))) -> CPR/AED 0.5;
A21: Bean, Michael | B21: 1048888 | C21: 46387 | D21: =IF(C21="","",DATE(YEAR(C21)-1,1,1)) -> 45658 | E21: =IF(C21="","",DATE(YEAR(C21),12,31)) -> 46387 | F21: =IF(OR(A21="",C21=""),"",SUMPRODUCT(('Training Detail'!$A$5:$A$5000=A21)*('Training Detail'!$M$5:$M$5000=Standards!A2)*('Training Detail'!$G$5:$G$5000>=D21)*('Training Detail'!$G$5:$G$5000<=E21)*('Training Detail'!$P$5:$P$5000))) -> 3 | G21: =IF(OR(A21="",C21=""),"",SUMPRODUCT(('Training Detail'!$A$5:$A$5000=A21)*('Training Detail'!$M$5:$M$5000=Standards!A3)*('Training Detail'!$G$5:$G$5000>=D21)*('Training Detail'!$G$5:$G$5000<=E21)*('Training Detail'!$P$5:$P$5000))) -> 3.5 | H21: =IF(OR(A21="",C21=""),"",SUMPRODUCT(('Training Detail'!$A$5:$A$5000=A21)*('Training Detail'!$M$5:$M$5000=Standards!A4)*('Training Detail'!$G$5:$G$5000>=D21)*('Training Detail'!$G$5:$G$5000<=E21)*('Training Detail'!$P$5:$P$5000))) -> 22 | I21: =IF(OR(A21="",C21=""),"",SUMPRODUCT(('Training Detail'!$A$5:$A$5000=A21)*('Training Detail'!$M$5:$M$5000=Standards!A5)*('Training Detail'!$G$5:$G$5000>=D21)*('Training Detail'!$G$5:$G$5000<=E21)*('Training Detail'!$P$5:$P$5000))) -> 11 | J21: =IF(OR(A21="",C21=""),"",SUMPRODUCT(('Training Detail'!$A$5:$A$5000=A21)*('Training Detail'!$M$5:$M$5000=Standards!A6)*('Training Detail'!$G$5:$G$5000>=D21)*('Training Detail'!$G$5:$G$5000<=E21)*('Training Detail'!$P$5:$P$5000))) -> 5 | K21: =IF(OR(A21="",C21=""),"",SUMPRODUCT(('Training Detail'!$A$5:$A$5000=A21)*('Training Detail'!$M$5:$M$5000=Standards!A7)*('Training Detail'!$G$5:$G$5000>=D21)*('Training Detail'!$G$5:$G$5000<=E21)*('Training Detail'!$P$5:$P$5000))) -> 1 | L21: =IF(OR(A21="",C21=""),"",SUMPRODUCT(('Training Detail'!$A$5:$A$5000=A21)*('Training Detail'!$M$5:$M$5000=Standards!A8)*('Training Detail'!$G$5:$G$5000>=D21)*('Training Detail'!$G$5:$G$5000<=E21)*('Training Detail'!$P$5:$P$5000))) -> 0 | M21: =IF(OR(A21="",C21=""),"",SUMPRODUCT(('Training Detail'!$A$5:$A$5000=A21)*('Training Detail'!$M$5:$M$5000=Standards!A9)*('Training Detail'!$G$5:$G$5000>=D21)*('Training Detail'!$G$5:$G$5000<=E21)*('Training Detail'!$P$5:$P$5000))) -> 0 | N21: =IF(A21="","",IF(C21="","Set exp date",IF(AND(F21>=Requirements!B5,G21>=Requirements!B6,H21>=Requirements!B7,I21>=Requirements!B8,J21>=Requirements!B9,K21>=Requirements!B10,L21>=Requirements!B11,M21>=Requirements!B12),"Met","Short"))) -> Short | O21: =IF(OR(A21="",C21=""),"",IF(N21="Met","",IF(F21<Requirements!B5,Requirements!A5&" "&TEXT(Requirements!B5-F21,"0.##")&"; ","")&IF(G21<Requirements!B6,Requirements!A6&" "&TEXT(Requirements!B6-G21,"0.##")&"; ","")&IF(H21<Requirements!B7,Requirements!A7&" "&TEXT(Requirements!B7-H21,"0.##")&"; ","")&IF(I21<Requirements!B8,Requirements!A8&" "&TEXT(Requirements!B8-I21,"0.##")&"; ","")&IF(J21<Requirements!B9,Requirements!A9&" "&TEXT(Requirements!B9-J21,"0.##")&"; ","")&IF(K21<Requirements!B10,Requirements!A10&" "&TEXT(Requirements!B10-K21,"0.##")&"; ","")&IF(L21<Requirements!B11,Requirements!A11&" "&TEXT(Requirements!B11-L21,"0.##")&"; ","")&IF(M21<Requirements!B12,Requirements!A12&" "&TEXT(Requirements!B12-M21,"0.##")&"; ",""))) -> Airway 1; Cardiovascular 1.5; SVAT 1; CPR/AED 1;
A22: Blair, Dustin | D22: =IF(C22="","",DATE(YEAR(C22)-1,1,1)) | E22: =IF(C22="","",DATE(YEAR(C22),12,31)) | F22: =IF(OR(A22="",C22=""),"",SUMPRODUCT(('Training Detail'!$A$5:$A$5000=A22)*('Training Detail'!$M$5:$M$5000=Standards!A2)*('Training Detail'!$G$5:$G$5000>=D22)*('Training Detail'!$G$5:$G$5000<=E22)*('Training Detail'!$P$5:$P$5000))) | G22: =IF(OR(A22="",C22=""),"",SUMPRODUCT(('Training Detail'!$A$5:$A$5000=A22)*('Training Detail'!$M$5:$M$5000=Standards!A3)*('Training Detail'!$G$5:$G$5000>=D22)*('Training Detail'!$G$5:$G$5000<=E22)*('Training Detail'!$P$5:$P$5000))) | H22: =IF(OR(A22="",C22=""),"",SUMPRODUCT(('Training Detail'!$A$5:$A$5000=A22)*('Training Detail'!$M$5:$M$5000=Standards!A4)*('Training Detail'!$G$5:$G$5000>=D22)*('Training Detail'!$G$5:$G$5000<=E22)*('Training Detail'!$P$5:$P$5000))) | I22: =IF(OR(A22="",C22=""),"",SUMPRODUCT(('Training Detail'!$A$5:$A$5000=A22)*('Training Detail'!$M$5:$M$5000=Standards!A5)*('Training Detail'!$G$5:$G$5000>=D22)*('Training Detail'!$G$5:$G$5000<=E22)*('Training Detail'!$P$5:$P$5000))) | J22: =IF(OR(A22="",C22=""),"",SUMPRODUCT(('Training Detail'!$A$5:$A$5000=A22)*('Training Detail'!$M$5:$M$5000=Standards!A6)*('Training Detail'!$G$5:$G$5000>=D22)*('Training Detail'!$G$5:$G$5000<=E22)*('Training Detail'!$P$5:$P$5000))) | K22: =IF(OR(A22="",C22=""),"",SUMPRODUCT(('Training Detail'!$A$5:$A$5000=A22)*('Training Detail'!$M$5:$M$5000=Standards!A7)*('Training Detail'!$G$5:$G$5000>=D22)*('Training Detail'!$G$5:$G$5000<=E22)*('Training Detail'!$P$5:$P$5000))) | L22: =IF(OR(A22="",C22=""),"",SUMPRODUCT(('Training Detail'!$A$5:$A$5000=A22)*('Training Detail'!$M$5:$M$5000=Standards!A8)*('Training Detail'!$G$5:$G$5000>=D22)*('Training Detail'!$G$5:$G$5000<=E22)*('Training Detail'!$P$5:$P$5000))) | M22: =IF(OR(A22="",C22=""),"",SUMPRODUCT(('Training Detail'!$A$5:$A$5000=A22)*('Training Detail'!$M$5:$M$5000=Standards!A9)*('Training Detail'!$G$5:$G$5000>=D22)*('Training Detail'!$G$5:$G$5000<=E22)*('Training Detail'!$P$5:$P$5000))) | N22: =IF(A22="","",IF(C22="","Set exp date",IF(AND(F22>=Requirements!B5,G22>=Requirements!B6,H22>=Requirements!B7,I22>=Requirements!B8,J22>=Requirements!B9,K22>=Requirements!B10,L22>=Requirements!B11,M22>=Requirements!B12),"Met","Short"))) -> Set exp date | O22: =IF(OR(A22="",C22=""),"",IF(N22="Met","",IF(F22<Requirements!B5,Requirements!A5&" "&TEXT(Requirements!B5-F22,"0.##")&"; ","")&IF(G22<Requirements!B6,Requirements!A6&" "&TEXT(Requirements!B6-G22,"0.##")&"; ","")&IF(H22<Requirements!B7,Requirements!A7&" "&TEXT(Requirements!B7-H22,"0.##")&"; ","")&IF(I22<Requirements!B8,Requirements!A8&" "&TEXT(Requirements!B8-I22,"0.##")&"; ","")&IF(J22<Requirements!B9,Requirements!A9&" "&TEXT(Requirements!B9-J22,"0.##")&"; ","")&IF(K22<Requirements!B10,Requirements!A10&" "&TEXT(Requirements!B10-K22,"0.##")&"; ","")&IF(L22<Requirements!B11,Requirements!A11&" "&TEXT(Requirements!B11-L22,"0.##")&"; ","")&IF(M22<Requirements!B12,Requirements!A12&" "&TEXT(Requirements!B12-M22,"0.##")&"; ","")))
A23: Blair, Scott | B23: 1053283 | C23: 46387 | D23: =IF(C23="","",DATE(YEAR(C23)-1,1,1)) -> 45658 | E23: =IF(C23="","",DATE(YEAR(C23),12,31)) -> 46387 | F23: =IF(OR(A23="",C23=""),"",SUMPRODUCT(('Training Detail'!$A$5:$A$5000=A23)*('Training Detail'!$M$5:$M$5000=Standards!A2)*('Training Detail'!$G$5:$G$5000>=D23)*('Training Detail'!$G$5:$G$5000<=E23)*('Training Detail'!$P$5:$P$5000))) -> 4 | G23: =IF(OR(A23="",C23=""),"",SUMPRODUCT(('Training Detail'!$A$5:$A$5000=A23)*('Training Detail'!$M$5:$M$5000=Standards!A3)*('Training Detail'!$G$5:$G$5000>=D23)*('Training Detail'!$G$5:$G$5000<=E23)*('Training Detail'!$P$5:$P$5000))) -> 0 | H23: =IF(OR(A23="",C23=""),"",SUMPRODUCT(('Training Detail'!$A$5:$A$5000=A23)*('Training Detail'!$M$5:$M$5000=Standards!A4)*('Training Detail'!$G$5:$G$5000>=D23)*('Training Detail'!$G$5:$G$5000<=E23)*('Training Detail'!$P$5:$P$5000))) -> 6 | I23: =IF(OR(A23="",C23=""),"",SUMPRODUCT(('Training Detail'!$A$5:$A$5000=A23)*('Training Detail'!$M$5:$M$5000=Standards!A5)*('Training Detail'!$G$5:$G$5000>=D23)*('Training Detail'!$G$5:$G$5000<=E23)*('Training Detail'!$P$5:$P$5000))) -> 10 | J23: =IF(OR(A23="",C23=""),"",SUMPRODUCT(('Training Detail'!$A$5:$A$5000=A23)*('Training Detail'!$M$5:$M$5000=Standards!A6)*('Training Detail'!$G$5:$G$5000>=D23)*('Training Detail'!$G$5:$G$5000<=E23)*('Training Detail'!$P$5:$P$5000))) -> 0 | K23: =IF(OR(A23="",C23=""),"",SUMPRODUCT(('Training Detail'!$A$5:$A$5000=A23)*('Training Detail'!$M$5:$M$5000=Standards!A7)*('Training Detail'!$G$5:$G$5000>=D23)*('Training Detail'!$G$5:$G$5000<=E23)*('Training Detail'!$P$5:$P$5000))) -> 1 | L23: =IF(OR(A23="",C23=""),"",SUMPRODUCT(('Training Detail'!$A$5:$A$5000=A23)*('Training Detail'!$M$5:$M$5000=Standards!A8)*('Training Detail'!$G$5:$G$5000>=D23)*('Training Detail'!$G$5:$G$5000<=E23)*('Training Detail'!$P$5:$P$5000))) -> 0 | M23: =IF(OR(A23="",C23=""),"",SUMPRODUCT(('Training Detail'!$A$5:$A$5000=A23)*('Training Detail'!$M$5:$M$5000=Standards!A9)*('Training Detail'!$G$5:$G$5000>=D23)*('Training Detail'!$G$5:$G$5000<=E23)*('Training Detail'!$P$5:$P$5000))) -> 0 | N23: =IF(A23="","",IF(C23="","Set exp date",IF(AND(F23>=Requirements!B5,G23>=Requirements!B6,H23>=Requirements!B7,I23>=Requirements!B8,J23>=Requirements!B9,K23>=Requirements!B10,L23>=Requirements!B11,M23>=Requirements!B12),"Met","Short"))) -> Short | O23: =IF(OR(A23="",C23=""),"",IF(N23="Met","",IF(F23<Requirements!B5,Requirements!A5&" "&TEXT(Requirements!B5-F23,"0.##")&"; ","")&IF(G23<Requirements!B6,Requirements!A6&" "&TEXT(Requirements!B6-G23,"0.##")&"; ","")&IF(H23<Requirements!B7,Requirements!A7&" "&TEXT(Requirements!B7-H23,"0.##")&"; ","")&IF(I23<Requirements!B8,Requirements!A8&" "&TEXT(Requirements!B8-I23,"0.##")&"; ","")&IF(J23<Requirements!B9,Requirements!A9&" "&TEXT(Requirements!B9-J23,"0.##")&"; ","")&IF(K23<Requirements!B10,Requirements!A10&" "&TEXT(Requirements!B10-K23,"0.##")&"; ","")&IF(L23<Requirements!B11,Requirements!A11&" "&TEXT(Requirements!B11-L23,"0.##")&"; ","")&IF(M23<Requirements!B12,Requirements!A12&" "&TEXT(Requirements!B12-M23,"0.##")&"; ",""))) -> Cardiovascular 5; Operations 2; SVAT 1; CPR/AED 1;
A24: Britton, Chris | B24: 1117145 | C24: 46387 | D24: =IF(C24="","",DATE(YEAR(C24)-1,1,1)) -> 45658 | E24: =IF(C24="","",DATE(YEAR(C24),12,31)) -> 46387 | F24: =IF(OR(A24="",C24=""),"",SUMPRODUCT(('Training Detail'!$A$5:$A$5000=A24)*('Training Detail'!$M$5:$M$5000=Standards!A2)*('Training Detail'!$G$5:$G$5000>=D24)*('Training Detail'!$G$5:$G$5000<=E24)*('Training Detail'!$P$5:$P$5000))) -> 0 | G24: =IF(OR(A24="",C24=""),"",SUMPRODUCT(('Training Detail'!$A$5:$A$5000=A24)*('Training Detail'!$M$5:$M$5000=Standards!A3)*('Training Detail'!$G$5:$G$5000>=D24)*('Training Detail'!$G$5:$G$5000<=E24)*('Training Detail'!$P$5:$P$5000))) -> 0 | H24: =IF(OR(A24="",C24=""),"",SUMPRODUCT(('Training Detail'!$A$5:$A$5000=A24)*('Training Detail'!$M$5:$M$5000=Standards!A4)*('Training Detail'!$G$5:$G$5000>=D24)*('Training Detail'!$G$5:$G$5000<=E24)*('Training Detail'!$P$5:$P$5000))) -> 2 | I24: =IF(OR(A24="",C24=""),"",SUMPRODUCT(('Training Detail'!$A$5:$A$5000=A24)*('Training Detail'!$M$5:$M$5000=Standards!A5)*('Training Detail'!$G$5:$G$5000>=D24)*('Training Detail'!$G$5:$G$5000<=E24)*('Training Detail'!$P$5:$P$5000))) -> 2.5 | J24: =IF(OR(A24="",C24=""),"",SUMPRODUCT(('Training Detail'!$A$5:$A$5000=A24)*('Training Detail'!$M$5:$M$5000=Standards!A6)*('Training Detail'!$G$5:$G$5000>=D24)*('Training Detail'!$G$5:$G$5000<=E24)*('Training Detail'!$P$5:$P$5000))) -> 2 | K24: =IF(OR(A24="",C24=""),"",SUMPRODUCT(('Training Detail'!$A$5:$A$5000=A24)*('Training Detail'!$M$5:$M$5000=Standards!A7)*('Training Detail'!$G$5:$G$5000>=D24)*('Training Detail'!$G$5:$G$5000<=E24)*('Training Detail'!$P$5:$P$5000))) -> 0 | L24: =IF(OR(A24="",C24=""),"",SUMPRODUCT(('Training Detail'!$A$5:$A$5000=A24)*('Training Detail'!$M$5:$M$5000=Standards!A8)*('Training Detail'!$G$5:$G$5000>=D24)*('Training Detail'!$G$5:$G$5000<=E24)*('Training Detail'!$P$5:$P$5000))) -> 0 | M24: =IF(OR(A24="",C24=""),"",SUMPRODUCT(('Training Detail'!$A$5:$A$5000=A24)*('Training Detail'!$M$5:$M$5000=Standards!A9)*('Training Detail'!$G$5:$G$5000>=D24)*('Training Detail'!$G$5:$G$5000<=E24)*('Training Detail'!$P$5:$P$5000))) -> 0.5 | N24: =IF(A24="","",IF(C24="","Set exp date",IF(AND(F24>=Requirements!B5,G24>=Requirements!B6,H24>=Requirements!B7,I24>=Requirements!B8,J24>=Requirements!B9,K24>=Requirements!B10,L24>=Requirements!B11,M24>=Requirements!B12),"Met","Short"))) -> Short | O24: =IF(OR(A24="",C24=""),"",IF(N24="Met","",IF(F24<Requirements!B5,Requirements!A5&" "&TEXT(Requirements!B5-F24,"0.##")&"; ","")&IF(G24<Requirements!B6,Requirements!A6&" "&TEXT(Requirements!B6-G24,"0.##")&"; ","")&IF(H24<Requirements!B7,Requirements!A7&" "&TEXT(Requirements!B7-H24,"0.##")&"; ","")&IF(I24<Requirements!B8,Requirements!A8&" "&TEXT(Requirements!B8-I24,"0.##")&"; ","")&IF(J24<Requirements!B9,Requirements!A9&" "&TEXT(Requirements!B9-J24,"0.##")&"; ","")&IF(K24<Requirements!B10,Requirements!A10&" "&TEXT(Requirements!B10-K24,"0.##")&"; ","")&IF(L24<Requirements!B11,Requirements!A11&" "&TEXT(Requirements!B11-L24,"0.##")&"; ","")&IF(M24<Requirements!B12,Requirements!A12&" "&TEXT(Requirements!B12-M24,"0.##")&"; ",""))) -> Airway 4; Cardiovascular 5; Trauma 1; Medical 3.5; PAHT 1; SVAT 1; CPR/AED 0.5;
A25: Buchanon, Chris | B25: 1051664 | C25: 46387 | D25: =IF(C25="","",DATE(YEAR(C25)-1,1,1)) -> 45658 | E25: =IF(C25="","",DATE(YEAR(C25),12,31)) -> 46387 | F25: =IF(OR(A25="",C25=""),"",SUMPRODUCT(('Training Detail'!$A$5:$A$5000=A25)*('Training Detail'!$M$5:$M$5000=Standards!A2)*('Training Detail'!$G$5:$G$5000>=D25)*('Training Detail'!$G$5:$G$5000<=E25)*('Training Detail'!$P$5:$P$5000))) -> 0 | G25: =IF(OR(A25="",C25=""),"",SUMPRODUCT(('Training Detail'!$A$5:$A$5000=A25)*('Training Detail'!$M$5:$M$5000=Standards!A3)*('Training Detail'!$G$5:$G$5000>=D25)*('Training Detail'!$G$5:$G$5000<=E25)*('Training Detail'!$P$5:$P$5000))) -> 2 | H25: =IF(OR(A25="",C25=""),"",SUMPRODUCT(('Training Detail'!$A$5:$A$5000=A25)*('Training Detail'!$M$5:$M$5000=Standards!A4)*('Training Detail'!$G$5:$G$5000>=D25)*('Training Detail'!$G$5:$G$5000<=E25)*('Training Detail'!$P$5:$P$5000))) -> 7 | I25: =IF(OR(A25="",C25=""),"",SUMPRODUCT(('Training Detail'!$A$5:$A$5000=A25)*('Training Detail'!$M$5:$M$5000=Standards!A5)*('Training Detail'!$G$5:$G$5000>=D25)*('Training Detail'!$G$5:$G$5000<=E25)*('Training Detail'!$P$5:$P$5000))) -> 3.5 | J25: =IF(OR(A25="",C25=""),"",SUMPRODUCT(('Training Detail'!$A$5:$A$5000=A25)*('Training Detail'!$M$5:$M$5000=Standards!A6)*('Training Detail'!$G$5:$G$5000>=D25)*('Training Detail'!$G$5:$G$5000<=E25)*('Training Detail'!$P$5:$P$5000))) -> 2 | K25: =IF(OR(A25="",C25=""),"",SUMPRODUCT(('Training Detail'!$A$5:$A$5000=A25)*('Training Detail'!$M$5:$M$5000=Standards!A7)*('Training Detail'!$G$5:$G$5000>=D25)*('Training Detail'!$G$5:$G$5000<=E25)*('Training Detail'!$P$5:$P$5000))) -> 0 | L25: =IF(OR(A25="",C25=""),"",SUMPRODUCT(('Training Detail'!$A$5:$A$5000=A25)*('Training Detail'!$M$5:$M$5000=Standards!A8)*('Training Detail'!$G$5:$G$5000>=D25)*('Training Detail'!$G$5:$G$5000<=E25)*('Training Detail'!$P$5:$P$5000))) -> 0 | M25: =IF(OR(A25="",C25=""),"",SUMPRODUCT(('Training Detail'!$A$5:$A$5000=A25)*('Training Detail'!$M$5:$M$5000=Standards!A9)*('Training Detail'!$G$5:$G$5000>=D25)*('Training Detail'!$G$5:$G$5000<=E25)*('Training Detail'!$P$5:$P$5000))) -> 3 | N25: =IF(A25="","",IF(C25="","Set exp date",IF(AND(F25>=Requirements!B5,G25>=Requirements!B6,H25>=Requirements!B7,I25>=Requirements!B8,J25>=Requirements!B9,K25>=Requirements!B10,L25>=Requirements!B11,M25>=Requirements!B12),"Met","Short"))) -> Short | O25: =IF(OR(A25="",C25=""),"",IF(N25="Met","",IF(F25<Requirements!B5,Requirements!A5&" "&TEXT(Requirements!B5-F25,"0.##")&"; ","")&IF(G25<Requirements!B6,Requirements!A6&" "&TEXT(Requirements!B6-G25,"0.##")&"; ","")&IF(H25<Requirements!B7,Requirements!A7&" "&TEXT(Requirements!B7-H25,"0.##")&"; ","")&IF(I25<Requirements!B8,Requirements!A8&" "&TEXT(Requirements!B8-I25,"0.##")&"; ","")&IF(J25<Requirements!B9,Requirements!A9&" "&TEXT(Requirements!B9-J25,"0.##")&"; ","")&IF(K25<Requirements!B10,Requirements!A10&" "&TEXT(Requirements!B10-K25,"0.##")&"; ","")&IF(L25<Requirements!B11,Requirements!A11&" "&TEXT(Requirements!B11-L25,"0.##")&"; ","")&IF(M25<Requirements!B12,Requirements!A12&" "&TEXT(Requirements!B12-M25,"0.##")&"; ",""))) -> Airway 4; Cardiovascular 3; Medical 2.5; PAHT 1; SVAT 1;
